Workbook

Sheet Contract
A1: SALES CONTRACT
D3: DATE: | E3: =Invoice!G9 -> 45994
D4: CONTRACT NO.: | E4: =Invoice!G8 -> JF25058
A5: The Seller: | B5: CALIFOR UPHOLSTERY MATERIALS CO.,LTD.
B6: XIN BAVET SEZ, Road No. 316A, Trapeang Bon and Prey Kokir Villages, Prey Kokir Commune, Chantrea District,
B7: Svay Rieng Province, Kingdom of Cambodia.
A8: TEL: | B8: +855 975910636
A9: The Buyer: | B9: JASON FURNITURE VIET NAM COMPANY LIMITED
B10: LOT 37, 38, 39, 40, 41, 44, 50, 51, 54，55, 56，B2 CLUSTER, DONG XOAI III INDUSTRIAL ZONE,
B11: BINH PHUOC WARD, DONG NAI PROVINCE, VIETNAM
A12: Contact Person : Contact Person : Mr. Thuy Tel: 0379367084
A13: EMAll:jyangbin4720@dingtalk.com jialy@kukahome.com dailin@kukahome.com huanggf@kukahome.com zhangzp@kukahome.com
A14: The undersigned Sellers 、Buyers and Beneficiary have agreed to close the following transactions according to the terms and conditions Stipulated below:
A15: No. | B15: ITEM Nº | C15: Quantity(SF) | D15: Unit Price(USD) | E15: Total value(USD)
A16: 1 | B16: 01.10.U756061 | C16: 5994.2 | D16: =E16/C16 -> 1.2425448 | E16: 7448.062
A17: 2 | B17: 01.10.W783010 | C17: 25340.4 | D17: =E17/C17 -> 1.51 | E17: 38264.004
A18: 3 | B18: 01.10.U528073 | C18: 4849.8 | D18: =E18/C18 -> 1.243161 | E18: 6029.082
A19: 4 | B19: 01.10.U528103 | C19: 29705.7 | D19: =E19/C19 -> 1.2675195 | E19: 37652.555
A20: 5 | B20: 01.10.W783010 | C20: 6619.4 | D20: =E20/C20 -> 1.5065012 | E20: 9972.134
A21: 6 | B21: 01.10.W782023 | C21: 12526.7 | D21: =E21/C21 -> 1.3715553 | E21: 17181.062
A22: 7 | B22: 01.10.W782023 | C22: 5531.5 | D22: =E22/C22 -> 1.3780005 | E22: 7622.41
A23: 8 | B23: 01.10.W782011 | C23: 15433.4 | D23: =E23/C23 -> 1.3796426 | E23: 21292.576
A24: 9 | B24: 01.10.W782033 | C24: 18657.4 | D24: =E24/C24 -> 1.3760778 | E24: 25674.034
A25: 10 | B25: 01.10.U562013-K | C25: 6134.9 | D25: =E25/C25 -> 1.52 | E25: 9325.048
A26: 11 | B26: 01.10.U562013-K | C26: 5443.7 | D26: =E26/C26 -> 1.4871822 | E26: 8095.774
A27: 12 | B27: 01.10.U528103 | C27: 2097.6 | D27: =E27/C27 -> 1.27 | E27: 2663.952
A28: TOTAL: | C28: =SUM(C16:C27) -> 138334.7 | E28: =SUM(E16:E27) -> 191220.69
A29: FCA: | B29: BAVET, SVAY RIENG
A30: Term of Payment: 100% TT after shipment
A31: Transaction method: FCA(USD)
A32: Beneficiary bank information: | C32: CALIFOR UPHOLSTERY MATERIALS CO.,LTD.
A33: Beneficiary Bank' s Name: | C33: BANK OF CHINA(HONG KONG)LIMITED PHNOM PENH BRANCH /BANK OF CHINA PHNOM PENH BRANCH
A34: Bank Address: | C34: 1st AND 2nd FLOOR,CANADIA TOWER,No.315 ANDDUONG ST. PHNOM PEMH,CAMBODIA.
A35: Bank account : | C35: 100001100764430
A36: SWIFT CODE ： | C36: BKCHKHPPXXX
A38: The Buyer: | D38: The Seller:
A39: JASON FURNITURE VIET NAM COMPANY LIMITED | D39: CALIFOR UPHOLSTERY MATERIALS CO.,LTD.

Sheet Invoice
A1: CALIFOR UPHOLSTERY MATERIALS CO., LTD.
A2: XIN BAVET SEZ, Road No. 316A, Trapeang Bon and Prey Kokir Villages, Prey Kokir Commune, Chantrea District,
A3: Svay Rieng Province, Kingdom of Cambodia.
A4: VAT:L001-901903209
A5: Tel: +855 975910636
A6: INVOICE
F7: Ref No.: | G7: ='Packing list'!I7 -> CLF2025-382
A8: EXPORTER: | B8: CALIFOR UPHOLSTERY MATERIALS CO., LTD. | F8: INVOICE NO : | G8: ='Packing list'!I8 -> JF25058
B9: XIN BAVET SEZ, Road No. 316A, Trapeang Bon and Prey Kokir Villages, | F9: Date: | G9: ='Packing list'!I9 -> 45994
B10: Prey Kokir Commune, Chantrea District,Svay Rieng Province, Kingdom of Cambodia | F10: FCA : | G10: BAVET, SVAYRIENG
B11: Tel: +855 975910636
A13: CONSIGNEE : | B13: JASON FURNITURE VIET NAM COMPANY LIMITED
B14: LOT 37, 38, 39, 40, 41, 44, 50, 51, 54，55, 56，B2 CLUSTER, DONG XOAI III INDUSTRIAL ZONE,
B15: BINH PHUOC WARD,DONG NAI PROVINCE, VIETNAM
B16: Contact Person : Mr. Thuy TEl: 0379367084
B17: EMAlL:jyangbin4720@dingtalk.com jialy@kukahome.com
B18: dailin@kukahome.com huanggf@kukahome.com zhangzp@kukahome.com
A19: SHIP: | B19: BY TRUCK FROM BAVET, SVAY RIENG, CAMBODIA TO DONG NAI PROVINCE, VIETNAM.
A21: Mark & Nº | B21: P.O. Nº | C21: ITEM Nº | D21: Description | E21: Quantity(SF) | F21: Unit price (USD) | G21: Amount (USD)
A22: VENDOR#: | B22: 9000761021 | C22: 01.10.U756061 | D22: LEATHER | E22: 5994.2 | F22: =G22/E22 -> 1.2425448 | G22: 7448.062
A23: Des: LEATHER | B23: 9000845799 | C23: 01.10.W783010 | E23: 25340.4 | F23: =G23/E23 -> 1.51 | G23: 38264.004
A24: MADE IN CAMBODIA | B24: 9000845799 | C24: 01.10.U528073 | E24: 4849.8 | F24: =G24/E24 -> 1.243161 | G24: 6029.082
B25: 9000845799 | C25: 01.10.U528103 | E25: 29705.7 | F25: =G25/E25 -> 1.2675195 | G25: 37652.555
B26: 9000837343 | C26: 01.10.W783010 | E26: 6619.4 | F26: =G26/E26 -> 1.5065012 | G26: 9972.134
B27: 9000827464 | C27: 01.10.W782023 | E27: 12526.7 | F27: =G27/E27 -> 1.3715553 | G27: 17181.062
B28: 9000840610 | C28: 01.10.W782023 | E28: 5531.5 | F28: =G28/E28 -> 1.3780005 | G28: 7622.41
B29: 9000822669 | C29: 01.10.W782011 | E29: 15433.4 | F29: =G29/E29 -> 1.3796426 | G29: 21292.576
B30: 9000804107 | C30: 01.10.W782033 | E30: 18657.4 | F30: =G30/E30 -> 1.3760778 | G30: 25674.034
B31: 9000824229 | C31: 01.10.U562013-K | E31: 6134.9 | F31: =G31/E31 -> 1.52 | G31: 9325.048
B32: 9000852084 | C32: 01.10.U562013-K | E32: 5443.7 | F32: =G32/E32 -> 1.4871822 | G32: 8095.774
B33: 9000846054 | C33: 01.10.U528103 | E33: 2097.6 | F33: =G33/E33 -> 1.27 | G33: 2663.952
B34: TOTAL: | C34: 21 PALLETS | E34: =SUM(E22:E33) -> 138334.7 | G34: =SUM(G22:G33) -> 191220.69
A35: Country of Original Cambodia
A36: Manufacture: | B36: CALIFOR UPHOLSTERY MATERIALS CO., LTD. XIN BAVET SEZ, Road No. 316A, Trapeang Bon and Prey Kokir Villages, Prey Kokir Commune, Chantrea District,Svay Rieng Province, Kingdom of Cambodia, Tel: +855 975910636
A37: BENEFICIARY BANK：BANK OF CHINA(HONG KONG)LIMITED PHNOM PENH BRANCH /BANK OF CHINA PHNOM PENH BRANCH
A38: A/C NO:100001100764430
A39: SWIFT CODE ：BKCHKHPPXXX
E40: CALIFOR UPHOLSTERY MATERIALS CO., LTD.
F41: Sign & Stamp
F46: ZENG XUELI

Sheet Packing list
A1: CALIFOR UPHOLSTERY MATERIALS CO., LTD.
A2: XIN BAVET SEZ, Road No. 316A, Trapeang Bon and Prey Kokir Villages, Prey Kokir Commune, Chantrea District,
A3: Svay Rieng Province, Kingdom of Cambodia.
A4: VAT:L001-901903209
A5: Tel: +855 975910636
A6: PACKING LIST
H7: Ref No.: | I7: CLF2025-382
A8: EXPORTER: | B8: CALIFOR UPHOLSTERY MATERIALS CO., LTD. | H8: INVOICE NO : | I8: JF25058
B9: XIN BAVET SEZ, Road No. 316A, Trapeang Bon and Prey Kokir Villages, | H9: Date: | I9: 45994
B10: Prey Kokir Commune, Chantrea District,Svay Rieng Province, Kingdom of Cambodia | H10: FCA : | I10: BAVET, SVAY RIENG
B11: Tel: +855 975910636
A13: CONSIGNEE : | B13: JASON FURNITURE VIET NAM COMPANY LIMITED
B14: LOT 37, 38, 39, 40, 41, 44, 50, 51, 54，55, 56，B2 CLUSTER, DONG XOAI III INDUSTRIAL ZONE,
B15: BINH PHUOC WARD,DONG NAI PROVINCE, VIETNAM
B16: Contact Person : Mr. Thuy TEl: 0379367084
B17: EMAlL:jyangbin4720@dingtalk.com jialy@kukahome.com
B18: dailin@kukahome.com huanggf@kukahome.com zhangzp@kukahome.com
A19: SHIP: | B19: BY TRUCK FROM BAVET, SVAY RIENG, CAMBODIA TO DONG NAI PROVINCE, VIETNAM.
A21: Mark & Nº | B21: P.O Nº | C21: ITEM Nº | D21: Description | E21: Quantity(SF) | G21: N.W (kgs) | H21: G.W (kgs) | I21: CBM
E22: PCS | F22: SF
A23: VENDOR#: | B23: 9000761021 | C23: 01.10.U756061 | D23: LEATHER | E23: 113 | F23: 5699.5 | G23: 481.6625 | H23: 524.0375 | I23: 1.8645
A24: Des: LEATHER | B24: 9000761021 | C24: 01.10.U756061 | E24: 4 | F24: 161.5 | G24: 17.05 | H24: 18.55 | I24: 0.066
A25: Case Qty: | B25: 9000761021 | C25: 01.10.U756061 | E25: 3 | F25: 133.2 | G25: 12.7875 | H25: 13.9125 | I25: 0.0495
A26: MADE IN CAMBODIA | B26: 9000845799 | C26: 01.10.W783010 | E26: 95 | F26: 5069.3 | G26: 513.5 | H26: 558.5 | I26: 1.98
B27: 9000845799 | C27: 01.10.W783010 | E27: 180 | F27: 10117.6 | G27: 1038.5 | H27: 1083.5 | I27: 3.0096
B28: 9000845799 | C28: 01.10.W783010 | E28: 180 | F28: 10153.5 | G28: 1021.5 | H28: 1066.5 | I28: 2.97
B29: 9000837343 | C29: 01.10.W783010 | E29: 120 | F29: 6465 | G29: 651.77419 | H29: 695.32258 | I29: 1.916129
B30: 9000837343 | C30: 01.10.W783010 | E30: 4 | F30: 154.4 | G30: 21.725806 | H30: 23.177419 | I30: 0.063870968
B31: 9000827464 | C31: 01.10.W782023 | E31: 115 | F31: 6287 | G31: 690 | H31: 735 | I31: 2.2572
B32: 9000827464 | C32: 01.10.W782023 | E32: 102 | F32: 5484.1 | G32: 577.01653 | H32: 614.95041 | I32: 1.7692364
B33: 9000827464 | C33: 01.10.W782023 | E33: 19 | F33: 755.6 | G33: 107.48347 | H33: 114.54959 | I33: 0.32956364
B34: 9000840610 | C34: 01.10.W782023 | E34: 97 | F34: 5452.5 | G34: 569.26263 | H34: 613.35354 | I34: 1.94
B35: 9000840610 | C35: 01.10.W782023 | E35: 2 | F35: 79 | G35: 11.737374 | H35: 12.646465 | I35: 0.04
B36: 9000822669 | C36: 01.10.W782011 | E36: 180 | F36: 10055.4 | G36: 1108 | H36: 1153 | I36: 2.9304
B37: 9000822669 | C37: 01.10.W782011 | E37: 94 | F37: 5338.6 | G37: 586.75789 | H37: 631.28421 | I37: 1.9591579
B38: 9000822669 | C38: 01.10.W782011 | E38: 1 | F38: 39.4 | G38: 6.2421053 | H38: 6.7157895 | I38: 0.020842105
... B47: 9000852084 | C47: 01.10.U562013-K | E47: 30 | F47: 1191 | G47: 119.49153 | H47: 130.9322 | I47: 0.45305085
B48: 9000845799 | C48: 01.10.U528073 | E48: 90 | F48: 4573.4 | G48: 361.85567 | H48: 403.60825 | I48: 1.4696907
B49: 9000845799 | C49: 01.10.U528073 | E49: 7 | F49: 276.4 | G49: 28.14433 | H49: 31.391753 | I49: 0.11430928
B50: 9000845799 | C50: 01.10.U528103 | E50: 103 | F50: 5458.8 | G50: 438 | H50: 483 | I50: 1.6632
...
